<?xml version='1.0' encoding='utf-8'?>
<sdf version="1.9">
  <model name="physicai_arm_so101">
    <self_collide>false</self_collide>
    <static>false</static>
    <allow_auto_disable>false</allow_auto_disable>
    <canonical_link>mount_link</canonical_link>
    <link name="mount_link">
      <gravity>false</gravity>
      <kinematic>false</kinematic>
      <inertial>
        <pose>0 0 0 0 0 0</pose>
        <mass>1e-6</mass>
        <inertia>
          <ixx>1e-9</ixx>
          <ixy>0</ixy>
          <ixz>0</ixz>
          <iyy>1e-9</iyy>
          <iyz>0</iyz>
          <izz>1e-9</izz>
        </inertia>
      </inertial>
    </link>
    <link name="base_link">
      <pose relative_to="mount_link">0 0 0.0024 0 0 0</pose>
      <inertial>
        <pose>0.0137179 -5.19711e-05 0.0334843 0 0 0</pose>
        <mass>0.147</mass>
        <inertia>
          <ixx>0.000114686</ixx>
          <ixy>-4.59787e-07</ixy>
          <ixz>4.97151e-06</ixz>
          <iyy>0.000136117</iyy>
          <iyz>9.75275e-08</iyz>
          <izz>0.000130364</izz>
        </inertia>
      </inertial>
      <visual name="visual_0">
        <pose>-0.00636471 -9.94414e-05 -0.0024 1.5708 -1.67685e-15 1.5708</pose>
        <geometry>
          <mesh>
            <uri>assets/base_motor_holder_so101_v1.stl</uri>
          </mesh>
        </geometry>
        <material>
          <ambient>1.0 0.82 0.12 1.0</ambient>
          <diffuse>1.0 0.82 0.12 1.0</diffuse>
          <specular>0 0 0 1</specular>
          <emissive>0 0 0 1</emissive>
        </material>
      </visual>
      <visual name="visual_1">
        <pose>-0.00636471 -8.97657e-09 -0.0024 1.5708 -2.78073e-29 1.5708</pose>
        <geometry>
          <mesh>
            <uri>assets/base_so101_v2.stl</uri>
          </mesh>
        </geometry>
        <material>
          <ambient>1.0 0.82 0.12 1.0</ambient>
          <diffuse>1.0 0.82 0.12 1.0</diffuse>
          <specular>0 0 0 1</specular>
          <emissive>0 0 0 1</emissive>
        </material>
      </visual>
      <visual name="visual_2">
        <pose>0.0263353 -8.97657e-09 0.0437 -8.21148e-16 7.84513e-18 1.249e-15</pose>
        <geometry>
          <mesh>
            <uri>assets/sts3215_03a_v1.stl</uri>
          </mesh>
        </geometry>
        <material>
          <ambient>0.1 0.1 0.1 1.0</ambient>
          <diffuse>0.1 0.1 0.1 1.0</diffuse>
          <specular>0 0 0 1</specular>
          <emissive>0 0 0 1</emissive>
        </material>
      </visual>
      <visual name="visual_3">
        <pose>-0.0309827 -0.000199441 0.0474 1.5708 -1.35493e-14 1.5708</pose>
        <geometry>
          <mesh>
            <uri>assets/waveshare_mounting_plate_so101_v2.stl</uri>
          </mesh>
        </geometry>
        <material>
          <ambient>1.0 0.82 0.12 1.0</ambient>
          <diffuse>1.0 0.82 0.12 1.0</diffuse>
          <specular>0 0 0 1</specular>
          <emissive>0 0 0 1</emissive>
        </material>
      </visual>
      <collision name="collision_0">
        <pose>0.012 0 0.036 0 0 0</pose>
        <geometry>
          <cylinder>
            <radius>0.052</radius>
            <length>0.065</length>
          </cylinder>
        </geometry>
        <max_contacts>3</max_contacts>
        <surface>
          <friction>
            <ode>
              <mu>0.8</mu>
              <mu2>0.8</mu2>
            </ode>
          </friction>
          <contact>
            <ode>
              <kp>1e6</kp>
              <kd>1e2</kd>
              <min_depth>0.0005</min_depth>
              <max_vel>0.1</max_vel>
            </ode>
          </contact>
        </surface>
      </collision>
    </link>
    <link name="shoulder_link">
      <pose relative_to="shoulder_pan">0 0 0 0 0 0</pose>
      <inertial>
        <pose>-0.0307604 -1.66727e-05 -0.0252713 0 0 0</pose>
        <mass>0.100006</mass>
        <inertia>
          <ixx>8.3759e-05</ixx>
          <ixy>7.55525e-08</ixy>
          <ixz>-1.16342e-06</ixz>
          <iyy>8.10403e-05</iyy>
          <iyz>1.54663e-07</iyz>
          <izz>2.39783e-05</izz>
        </inertia>
      </inertial>
      <visual name="visual_0">
        <pose>-0.0303992 0.000422241 -0.0417 1.5708 1.5708 0</pose>
        <geometry>
          <mesh>
            <uri>assets/sts3215_03a_v1.stl</uri>
          </mesh>
        </geometry>
        <material>
          <ambient>0.1 0.1 0.1 1.0</ambient>
          <diffuse>0.1 0.1 0.1 1.0</diffuse>
          <specular>0 0 0 1</specular>
          <emissive>0 0 0 1</emissive>
        </material>
      </visual>
      <visual name="visual_1">
        <pose>-0.0675992 -0.000177759 0.0158499 1.5708 -1.5708 0</pose>
        <geometry>
          <mesh>
            <uri>assets/motor_holder_so101_base_v1.stl</uri>
          </mesh>
        </geometry>
        <material>
          <ambient>1.0 0.82 0.12 1.0</ambient>
          <diffuse>1.0 0.82 0.12 1.0</diffuse>
          <specular>0 0 0 1</specular>
          <emissive>0 0 0 1</emissive>
        </material>
      </visual>
      <visual name="visual_2">
        <pose>0.0122008 2.22413e-05 0.0464 -1.5708 2.35221e-33 0</pose>
        <geometry>
          <mesh>
            <uri>assets/rotation_pitch_so101_v1.stl</uri>
          </mesh>
        </geometry>
        <material>
          <ambient>1.0 0.82 0.12 1.0</ambient>
          <diffuse>1.0 0.82 0.12 1.0</diffuse>
          <specular>0 0 0 1</specular>
          <emissive>0 0 0 1</emissive>
        </material>
      </visual>
      <collision name="collision_0">
        <pose>-0.020 0 -0.010 0 0 0</pose>
        <geometry>
          <box>
            <size>0.060 0.050 0.095</size>
          </box>
        </geometry>
        <max_contacts>3</max_contacts>
        <surface>
          <friction>
            <ode>
              <mu>0.8</mu>
              <mu2>0.8</mu2>
            </ode>
          </friction>
          <contact>
            <ode>
              <kp>1e6</kp>
              <kd>1e2</kd>
              <min_depth>0.0005</min_depth>
              <max_vel>0.1</max_vel>
            </ode>
          </contact>
        </surface>
      </collision>
    </link>
    <link name="upper_arm_link">
      <pose relative_to="shoulder_lift">0 0 0 0 0 0</pose>
      <inertial>
        <pose>-0.0898471 -0.00838224 0.0184089 0 0 0</pose>
        <mass>0.103</mass>
        <inertia>
          <ixx>4.08002e-05</ixx>
          <ixy>-1.97819e-05</ixy>
          <ixz>-4.03016e-08</ixz>
          <iyy>0.000147318</iyy>
          <iyz>8.97326e-09</iyz>
          <izz>0.000142487</izz>
        </inertia>
      </inertial>
      <visual name="visual_0">
        <pose>-0.11257 -0.0155 0.0187 -3.14159 -5.27356e-16 -1.5708</pose>
        <geometry>
          <mesh>
            <uri>assets/sts3215_03a_v1.stl</uri>
          </mesh>
        </geometry>
        <material>
          <ambient>0.1 0.1 0.1 1.0</ambient>
          <diffuse>0.1 0.1 0.1 1.0</diffuse>
          <specular>0 0 0 1</specular>
          <emissive>0 0 0 1</emissive>
        </material>
      </visual>
      <visual name="visual_1">
        <pose>-0.065085 0.012 0.0182 3.14159 -0 -1.30911e-30</pose>
        <geometry>
          <mesh>
            <uri>assets/upper_arm_so101_v1.stl</uri>
          </mesh>
        </geometry>
        <material>
          <ambient>1.0 0.82 0.12 1.0</ambient>
          <diffuse>1.0 0.82 0.12 1.0</diffuse>
          <specular>0 0 0 1</specular>
          <emissive>0 0 0 1</emissive>
        </material>
      </visual>
      <collision name="collision_0">
        <pose>-0.065 0.012 0.0182 0 0 0</pose>
        <geometry>
          <box>
            <size>0.135 0.042 0.050</size>
          </box>
        </geometry>
        <max_contacts>3</max_contacts>
        <surface>
          <friction>
            <ode>
              <mu>0.8</mu>
              <mu2>0.8</mu2>
            </ode>
          </friction>
          <contact>
            <ode>
              <kp>1e6</kp>
              <kd>1e2</kd>
              <min_depth>0.0005</min_depth>
              <max_vel>0.1</max_vel>
            </ode>
          </contact>
        </surface>
      </collision>
    </link>
    <link name="lower_arm_link">
      <pose relative_to="elbow_flex">0 0 0 0 0 0</pose>
      <inertial>
        <pose>-0.0980701 0.00324376 0.0182831 0 0 0</pose>
        <mass>0.104</mass>
        <inertia>
          <ixx>2.87438e-05</ixx>
          <ixy>7.41152e-06</ixy>
          <ixz>1.26409e-06</ixz>
          <iyy>0.000159844</iyy>
          <iyz>-4.90188e-08</iyz>
          <izz>0.00014529</izz>
        </inertia>
      </inertial>
      <visual name="visual_0">
        <pose>-0.0648499 -0.032 0.0182 3.14159 -0 6.67202e-31</pose>
        <geometry>
          <mesh>
            <uri>assets/under_arm_so101_v1.stl</uri>
          </mesh>
        </geometry>
        <material>
          <ambient>1.0 0.82 0.12 1.0</ambient>
          <diffuse>1.0 0.82 0.12 1.0</diffuse>
          <specular>0 0 0 1</specular>
          <emissive>0 0 0 1</emissive>
        </material>
      </visual>
      <visual name="visual_1">
        <pose>-0.0648499 -0.032 0.018 -3.14159 -2.55351e-15 -1.83387e-30</pose>
        <geometry>
          <mesh>
            <uri>assets/motor_holder_so101_wrist_v1.stl</uri>
          </mesh>
        </geometry>
        <material>
          <ambient>1.0 0.82 0.12 1.0</ambient>
          <diffuse>1.0 0.82 0.12 1.0</diffuse>
          <specular>0 0 0 1</specular>
          <emissive>0 0 0 1</emissive>
        </material>
      </visual>
      <visual name="visual_2">
        <pose>-0.1224 0.0052 0.0187 -3.14159 -7.88861e-31 -3.14159</pose>
        <geometry>
          <mesh>
            <uri>assets/sts3215_03a_v1.stl</uri>
          </mesh>
        </geometry>
        <material>
          <ambient>0.1 0.1 0.1 1.0</ambient>
          <diffuse>0.1 0.1 0.1 1.0</diffuse>
          <specular>0 0 0 1</specular>
          <emissive>0 0 0 1</emissive>
        </material>
      </visual>
      <collision name="collision_0">
        <pose>-0.067 0.003 0.020 0 0 0</pose>
        <geometry>
          <box>
            <size>0.145 0.036 0.048</size>
          </box>
        </geometry>
        <max_contacts>3</max_contacts>
        <surface>
          <friction>
            <ode>
              <mu>0.8</mu>
              <mu2>0.8</mu2>
            </ode>
          </friction>
          <contact>
            <ode>
              <kp>1e6</kp>
              <kd>1e2</kd>
              <min_depth>0.0005</min_depth>
              <max_vel>0.1</max_vel>
            </ode>
          </contact>
        </surface>
      </collision>
    </link>
    <link name="wrist_link">
      <pose relative_to="wrist_flex">0 0 0 0 0 0</pose>
      <inertial>
        <pose>-0.000103312 -0.0386143 0.0281156 0 0 0</pose>
        <mass>0.079</mass>
        <inertia>
          <ixx>3.68263e-05</ixx>
          <ixy>1.7893e-08</ixy>
          <ixz>-5.28128e-08</ixz>
          <iyy>2.5391e-05</iyy>
          <iyz>3.6412e-06</iyz>
          <izz>2.1e-05</izz>
        </inertia>
      </inertial>
      <visual name="visual_0">
        <pose>8.32667e-17 -0.0424 0.0306 1.5708 1.5708 0</pose>
        <geometry>
          <mesh>
            <uri>assets/sts3215_03a_no_horn_v1.stl</uri>
          </mesh>
        </geometry>
        <material>
          <ambient>0.1 0.1 0.1 1.0</ambient>
          <diffuse>0.1 0.1 0.1 1.0</diffuse>
          <specular>0 0 0 1</specular>
          <emissive>0 0 0 1</emissive>
        </material>
      </visual>
      <visual name="visual_1">
        <pose>0 -0.028 0.0181 -1.5708 -1.5708 0</pose>
        <geometry>
          <mesh>
            <uri>assets/wrist_roll_pitch_so101_v2.stl</uri>
          </mesh>
        </geometry>
        <material>
          <ambient>1.0 0.82 0.12 1.0</ambient>
          <diffuse>1.0 0.82 0.12 1.0</diffuse>
          <specular>0 0 0 1</specular>
          <emissive>0 0 0 1</emissive>
        </material>
      </visual>
      <collision name="collision_0">
        <pose>-0.002 -0.028 0.022 0 0 0</pose>
        <geometry>
          <box>
            <size>0.032 0.072 0.055</size>
          </box>
        </geometry>
        <max_contacts>3</max_contacts>
        <surface>
          <friction>
            <ode>
              <mu>0.8</mu>
              <mu2>0.8</mu2>
            </ode>
          </friction>
          <contact>
            <ode>
              <kp>1e6</kp>
              <kd>1e2</kd>
              <min_depth>0.0005</min_depth>
              <max_vel>0.1</max_vel>
            </ode>
          </contact>
        </surface>
      </collision>
    </link>
    <link name="gripper_link">
      <pose relative_to="wrist_roll">0 0 0 0 0 0</pose>
      <inertial>
        <pose>0.000213627 0.000245138 -0.025187 0 0 0</pose>
        <mass>0.087</mass>
        <inertia>
          <ixx>2.75087e-05</ixx>
          <ixy>-3.35241e-07</ixy>
          <ixz>-5.7352e-06</ixz>
          <iyy>4.33657e-05</iyy>
          <iyz>-5.17847e-08</iyz>
          <izz>3.45059e-05</izz>
        </inertia>
      </inertial>
      <visual name="visual_0">
        <pose>0.0077 0.0001 -0.0234 -1.5708 -5.19179e-17 -1.66533e-16</pose>
        <geometry>
          <mesh>
            <uri>assets/sts3215_03a_v1.stl</uri>
          </mesh>
        </geometry>
        <material>
          <ambient>0.1 0.1 0.1 1.0</ambient>
          <diffuse>0.1 0.1 0.1 1.0</diffuse>
          <specular>0 0 0 1</specular>
          <emissive>0 0 0 1</emissive>
        </material>
      </visual>
      <visual name="visual_1">
        <pose>8.32667e-17 -0.000218214 0.000949706 -3.14159 -5.55112e-17 0</pose>
        <geometry>
          <mesh>
            <uri>assets/wrist_roll_follower_so101_v1.stl</uri>
          </mesh>
        </geometry>
        <material>
          <ambient>1.0 0.82 0.12 1.0</ambient>
          <diffuse>1.0 0.82 0.12 1.0</diffuse>
          <specular>0 0 0 1</specular>
          <emissive>0 0 0 1</emissive>
        </material>
      </visual>
      <collision name="fixed_jaw_mesh">
        <pose>8.32667e-17 -0.000218214 0.000949706 -3.14159 -5.55112e-17 0</pose>
        <geometry>
          <mesh>
            <uri>assets/wrist_roll_follower_so101_v1.stl</uri>
          </mesh>
        </geometry>
        <max_contacts>6</max_contacts>
        <surface>
          <friction>
            <ode>
              <mu>0.3</mu>
              <mu2>0.3</mu2>
              <slip1>0.03</slip1>
              <slip2>0.03</slip2>
            </ode>
            <torsional>
              <coefficient>0.02</coefficient>
              <use_patch_radius>true</use_patch_radius>
              <patch_radius>0.002</patch_radius>
              <ode>
                <slip>0.03</slip>
              </ode>
            </torsional>
          </friction>
          <contact>
            <ode>
              <kp>8.0e4</kp>
              <kd>1.2e3</kd>
              <min_depth>0.0005</min_depth>
              <max_vel>0.015</max_vel>
            </ode>
          </contact>
        </surface>
      </collision>
      <collision name="fixed_jaw_pad">
        <pose>-0.0115 0 -0.0895 0 0 0</pose>
        <geometry>
          <box>
            <size>0.014 0.020 0.034</size>
          </box>
        </geometry>
        <max_contacts>4</max_contacts>
        <surface>
          <friction>
            <ode>
              <mu>8.0</mu>
              <mu2>8.0</mu2>
              <slip1>0.0</slip1>
              <slip2>0.0</slip2>
            </ode>
            <torsional>
              <coefficient>0.20</coefficient>
              <use_patch_radius>true</use_patch_radius>
              <patch_radius>0.0030</patch_radius>
              <ode>
                <slip>0.0</slip>
              </ode>
            </torsional>
          </friction>
          <contact>
            <ode>
              <kp>1.0e5</kp>
              <kd>2.0e3</kd>
              <min_depth>0.0008</min_depth>
              <max_vel>0.006</max_vel>
            </ode>
          </contact>
        </surface>
      </collision>
    </link>
    <link name="gripper_frame_link">
      <pose relative_to="gripper_frame_joint">0 0 0 0 0 0</pose>
      <inertial>
        <pose>0 0 0 0 0 0</pose>
        <mass>1e-9</mass>
        <inertia>
          <ixx>1e-12</ixx>
          <ixy>0</ixy>
          <ixz>0</ixz>
          <iyy>1e-12</iyy>
          <iyz>0</iyz>
          <izz>1e-12</izz>
        </inertia>
      </inertial>
    </link>
    <link name="moving_jaw_so101_v1_link">
      <pose relative_to="gripper">0 0 0 0 0 0</pose>
      <inertial>
        <pose>-0.00157495 -0.0300244 0.0192755 0 0 0</pose>
        <mass>0.012</mass>
        <inertia>
          <ixx>6.61427e-06</ixx>
          <ixy>-3.19807e-07</ixy>
          <ixz>-5.90717e-09</ixz>
          <iyy>1.89032e-06</iyy>
          <iyz>-1.09945e-07</iyz>
          <izz>5.28738e-06</izz>
        </inertia>
      </inertial>
      <visual name="visual_0">
        <pose>-5.55112e-17 -5.55112e-17 0.0189 9.53145e-17 6.93889e-18 1.24077e-24</pose>
        <geometry>
          <mesh>
            <uri>assets/moving_jaw_so101_v1.stl</uri>
          </mesh>
        </geometry>
        <material>
          <ambient>1.0 0.82 0.12 1.0</ambient>
          <diffuse>1.0 0.82 0.12 1.0</diffuse>
          <specular>0 0 0 1</specular>
          <emissive>0 0 0 1</emissive>
        </material>
      </visual>
      <collision name="moving_jaw_mesh">
        <pose>-5.55112e-17 -5.55112e-17 0.0189 9.53145e-17 6.93889e-18 1.24077e-24</pose>
        <geometry>
          <mesh>
            <uri>assets/moving_jaw_so101_v1.stl</uri>
          </mesh>
        </geometry>
        <max_contacts>6</max_contacts>
        <surface>
          <friction>
            <ode>
              <mu>0.3</mu>
              <mu2>0.3</mu2>
              <slip1>0.03</slip1>
              <slip2>0.03</slip2>
            </ode>
            <torsional>
              <coefficient>0.02</coefficient>
              <use_patch_radius>true</use_patch_radius>
              <patch_radius>0.002</patch_radius>
              <ode>
                <slip>0.03</slip>
              </ode>
            </torsional>
          </friction>
          <contact>
            <ode>
              <kp>8.0e4</kp>
              <kd>1.2e3</kd>
              <min_depth>0.0005</min_depth>
              <max_vel>0.015</max_vel>
            </ode>
          </contact>
        </surface>
      </collision>
      <collision name="moving_jaw_pad">
        <pose>-0.001 -0.058 0.019 0 0 0</pose>
        <geometry>
          <box>
            <size>0.014 0.024 0.026</size>
          </box>
        </geometry>
        <max_contacts>4</max_contacts>
        <surface>
          <friction>
            <ode>
              <mu>8.0</mu>
              <mu2>8.0</mu2>
              <slip1>0.0</slip1>
              <slip2>0.0</slip2>
            </ode>
            <torsional>
              <coefficient>0.20</coefficient>
              <use_patch_radius>true</use_patch_radius>
              <patch_radius>0.0030</patch_radius>
              <ode>
                <slip>0.0</slip>
              </ode>
            </torsional>
          </friction>
          <contact>
            <ode>
              <kp>1.0e5</kp>
              <kd>2.0e3</kd>
              <min_depth>0.0008</min_depth>
              <max_vel>0.006</max_vel>
            </ode>
          </contact>
        </surface>
      </collision>
      <collision name="moving_jaw_midlink_box">
        <pose>-0.002 -0.040 0.019 0 0 0</pose>
        <geometry>
          <box>
            <size>0.010 0.030 0.016</size>
          </box>
        </geometry>
        <max_contacts>4</max_contacts>
        <surface>
          <friction>
            <ode>
              <mu>0.8</mu>
              <mu2>0.8</mu2>
            </ode>
          </friction>
          <contact>
            <ode>
              <kp>1.0e5</kp>
              <kd>1.0e3</kd>
              <min_depth>0.0005</min_depth>
              <max_vel>0.02</max_vel>
            </ode>
          </contact>
        </surface>
      </collision>
    </link>
    <joint name="world_anchor" type="fixed">
      <parent>world</parent>
      <child>mount_link</child>
    </joint>
    <joint name="base_mount" type="fixed">
      <pose relative_to="mount_link">0 0 0.0024 0 0 0</pose>
      <parent>mount_link</parent>
      <child>base_link</child>
    </joint>
    <joint name="gripper_frame_joint" type="fixed">
      <pose relative_to="gripper_link">-0.0079 -0.000218121 -0.0981274 0 3.14159 0</pose>
      <parent>gripper_link</parent>
      <child>gripper_frame_link</child>
    </joint>
    <joint name="gripper" type="revolute">
      <pose relative_to="gripper_link">0.0202 0.0188 -0.0234 1.5708 -5.24284e-08 -1.41553e-15</pose>
      <parent>gripper_link</parent>
      <child>moving_jaw_so101_v1_link</child>
      <axis>
        <xyz>0 0 1</xyz>
        <dynamics>
          <damping>0.32</damping>
          <friction>0.025</friction>
        </dynamics>
        <limit>
          <lower>-0.174533</lower>
          <upper>1.74533</upper>
          <effort>32</effort>
          <velocity>10</velocity>
        </limit>
      </axis>
    </joint>
    <joint name="wrist_roll" type="revolute">
      <pose relative_to="wrist_link">5.55112e-17 -0.0611 0.0181 1.5708 0.0486795 3.14159</pose>
      <parent>wrist_link</parent>
      <child>gripper_link</child>
      <axis>
        <xyz>0 0 1</xyz>
        <dynamics>
          <damping>1.05</damping>
          <friction>0.09</friction>
        </dynamics>
        <limit>
          <lower>-2.74385</lower>
          <upper>2.84121</upper>
          <effort>28</effort>
          <velocity>16</velocity>
        </limit>
      </axis>
    </joint>
    <joint name="wrist_flex" type="revolute">
      <pose relative_to="lower_arm_link">-0.1349 0.0052 3.62355e-17 4.02456e-15 8.67362e-16 -1.5708</pose>
      <parent>lower_arm_link</parent>
      <child>wrist_link</child>
      <axis>
        <xyz>0 0 1</xyz>
        <dynamics>
          <damping>1.30</damping>
          <friction>0.13</friction>
        </dynamics>
        <limit>
          <lower>-1.65806</lower>
          <upper>1.65806</upper>
          <effort>45</effort>
          <velocity>20</velocity>
        </limit>
      </axis>
    </joint>
    <joint name="elbow_flex" type="revolute">
      <pose relative_to="upper_arm_link">-0.11257 -0.028 1.73763e-16 -3.63608e-16 8.74301e-16 1.5708</pose>
      <parent>upper_arm_link</parent>
      <child>lower_arm_link</child>
      <axis>
        <xyz>0 0 1</xyz>
        <dynamics>
          <damping>0.90</damping>
          <friction>0.08</friction>
        </dynamics>
        <limit>
          <lower>-1.69</lower>
          <upper>1.69</upper>
          <effort>35</effort>
          <velocity>15</velocity>
        </limit>
      </axis>
    </joint>
    <joint name="shoulder_lift" type="revolute">
      <pose relative_to="shoulder_link">-0.0303992 -0.0182778 -0.0542 -1.5708 -1.5708 0</pose>
      <parent>shoulder_link</parent>
      <child>upper_arm_link</child>
      <axis>
        <xyz>0 0 1</xyz>
        <dynamics>
          <damping>0.90</damping>
          <friction>0.08</friction>
        </dynamics>
        <limit>
          <lower>-1.74533</lower>
          <upper>1.74533</upper>
          <effort>40</effort>
          <velocity>15</velocity>
        </limit>
      </axis>
    </joint>
    <joint name="shoulder_pan" type="revolute">
      <pose relative_to="base_link">0.0388353 -8.97657e-09 0.0624 3.14159 4.18253e-17 -3.14159</pose>
      <parent>base_link</parent>
      <child>shoulder_link</child>
      <axis>
        <xyz>0 0 1</xyz>
        <dynamics>
          <damping>0.90</damping>
          <friction>0.08</friction>
        </dynamics>
        <limit>
          <lower>-1.91986</lower>
          <upper>1.91986</upper>
          <effort>40</effort>
          <velocity>15</velocity>
        </limit>
      </axis>
    </joint>
    <plugin filename="ignition-gazebo-joint-state-publisher-system" name="ignition::gazebo::systems::JointStatePublisher">
      <topic>/physicai_arm/joint_state</topic>
      <joint_name>shoulder_pan</joint_name>
      <joint_name>shoulder_lift</joint_name>
      <joint_name>elbow_flex</joint_name>
      <joint_name>wrist_flex</joint_name>
      <joint_name>wrist_roll</joint_name>
      <joint_name>gripper</joint_name>
    </plugin>
    <plugin filename="ignition-gazebo-joint-position-controller-system" name="ignition::gazebo::systems::JointPositionController">
      <joint_name>shoulder_pan</joint_name>
      <topic>/physicai_arm/cmd/shoulder_pan</topic>
      <initial_position>0.0</initial_position>
      <cmd_max>12</cmd_max>
      <cmd_min>-12</cmd_min>
      <p_gain>24</p_gain>
      <i_gain>0.0</i_gain>
      <d_gain>3.0</d_gain>
    </plugin>
    <plugin filename="ignition-gazebo-joint-position-controller-system" name="ignition::gazebo::systems::JointPositionController">
      <joint_name>shoulder_lift</joint_name>
      <topic>/physicai_arm/cmd/shoulder_lift</topic>
      <initial_position>0.0</initial_position>
      <cmd_max>14</cmd_max>
      <cmd_min>-14</cmd_min>
      <p_gain>28</p_gain>
      <i_gain>0.0</i_gain>
      <d_gain>3.5</d_gain>
    </plugin>
    <plugin filename="ignition-gazebo-joint-position-controller-system" name="ignition::gazebo::systems::JointPositionController">
      <joint_name>elbow_flex</joint_name>
      <topic>/physicai_arm/cmd/elbow_flex</topic>
      <initial_position>0.0</initial_position>
      <cmd_max>12</cmd_max>
      <cmd_min>-12</cmd_min>
      <p_gain>22</p_gain>
      <i_gain>0.0</i_gain>
      <d_gain>2.8</d_gain>
    </plugin>
    <plugin filename="ignition-gazebo-joint-position-controller-system" name="ignition::gazebo::systems::JointPositionController">
      <joint_name>wrist_flex</joint_name>
      <topic>/physicai_arm/cmd/wrist_flex</topic>
      <initial_position>0.0</initial_position>
      <cmd_max>10</cmd_max>
      <cmd_min>-10</cmd_min>
      <p_gain>26</p_gain>
      <i_gain>0.0</i_gain>
      <d_gain>3.0</d_gain>
    </plugin>
    <plugin filename="ignition-gazebo-joint-position-controller-system" name="ignition::gazebo::systems::JointPositionController">
      <joint_name>wrist_roll</joint_name>
      <topic>/physicai_arm/cmd/wrist_roll</topic>
      <initial_position>0.0</initial_position>
      <cmd_max>8</cmd_max>
      <cmd_min>-8</cmd_min>
      <p_gain>18</p_gain>
      <i_gain>0.0</i_gain>
      <d_gain>2.2</d_gain>
    </plugin>
    <plugin filename="ignition-gazebo-joint-position-controller-system" name="ignition::gazebo::systems::JointPositionController">
      <joint_name>gripper</joint_name>
      <topic>/physicai_arm/cmd/gripper</topic>
      <initial_position>0.80</initial_position>
      <cmd_max>3.2</cmd_max>
      <cmd_min>-3.2</cmd_min>
      <p_gain>6.5</p_gain>
      <i_gain>0.0</i_gain>
      <d_gain>0.8</d_gain>
    </plugin>
  </model>
</sdf>